<?xml version='1.0'?>

<robot name="udacity_bot" xmlns:xacro="http://www.ros.org/wiki/xacro">

  <!-- source: https://github.com/tu-darmstadt-ros-pkg/hector_models/blob/indigo-devel/hector_xacro_tools/urdf/inertia_tensors.urdf.xacro -->
  <xacro:include filename="$(find udacity_bot)/urdf/inertia_tensors.urdf.xacro" />

  <xacro:include filename="$(find udacity_bot)/urdf/custom_bot.gazebo" />

  <link name="robot_footprint"></link>

  <joint name="robot_footprint_joint" type="fixed">
    <origin xyz="0 0 0" rpy="0 0 0" />
    <parent link="robot_footprint"/>
    <child link="chassis" />
  </joint>

  <joint type="continuous" name="left_wheel_hinge">
    <origin xyz="0 0.23 -0.26" rpy="0 0 0"/>
    <child link="left_wheel"/>
    <parent link="chassis"/>
    <axis xyz="0 1 0" rpy="0 0 0"/>
    <limit effort="10000" velocity="1000"/>
    <joint_properties damping="1.0" friction="1.0"/>
  </joint>

  <joint type="continuous" name="right_wheel_hinge">
    <origin xyz="0 -0.23 -0.26" rpy="0 0 0"/>
    <child link="right_wheel"/>
    <parent link="chassis"/>
    <axis xyz="0 1 0" rpy="0 0 0"/>
    <limit effort="10000" velocity="1000"/>
    <joint_properties damping="1.0" friction="1.0"/>
  </joint>

  <joint type="fixed" name="camera_joint">
    <origin xyz="0.2 0 .2" rpy="0 0 0"/>
    <child link="camera"/>
    <parent link="chassis"/>
    <axis xyz="0 1 0" rpy="0 0 0"/>
    <limit effort="10000" velocity="1000"/>
    <joint_properties damping="1.0" friction="1.0"/>
  </joint>

  <joint type="fixed" name="hokuyo_joint">
    <origin xyz="0 0 0.335" rpy="0 0 0"/>
    <child link="hokuyo"/>
    <parent link="chassis"/>
    <axis xyz="0 1 0" rpy="0 0 0"/>
    <limit effort="10000" velocity="1000"/>
    <joint_properties damping="1.0" friction="1.0"/>
  </joint>

  <joint type="fixed" name="front_caster_joint">
    <origin xyz="0.15 0 -0.31" rpy="0 0 0"/>
    <child link="front_caster"/>
    <parent link="chassis"/>
    <axis xyz="0 1 0" rpy="0 0 0"/>
    <limit effort="10000" velocity="1000"/>
    <joint_properties damping="1.0" friction="1.0"/>
  </joint>

  <joint type="fixed" name="back_caster_joint">
    <origin xyz="-0.15 0 -0.31" rpy="0 0 0"/>
    <child link="back_caster"/>
    <parent link="chassis"/>
    <axis xyz="0 1 0" rpy="0 0 0"/>
    <limit effort="10000" velocity="1000"/>
    <joint_properties damping="1.0" friction="1.0"/>
  </joint>

  <link name='left_wheel'>
    <inertial>
      <mass value="5.0"/>
      <origin xyz="0.0 0 0" rpy=" 0 1.5707 1.5707"/>
      <inertia
          ixx="0.1" ixy="0" ixz="0"
          iyy="0.1" iyz="0"
          izz="0.1"
      />
    </inertial>

    <collision name='left_wheel_collision'>
      <origin xyz="0 0 0" rpy=" 0 1.5707 1.5707"/> 
      <geometry>
        <cylinder length="0.05" radius="0.1"/>
      </geometry>
    </collision>

    <visual name='left_wheel_visual'>
      <origin xyz="0 0 0" rpy=" 0 1.5707 1.5707"/>
      <geometry>
        <cylinder length="0.05" radius="0.1"/>
      </geometry>
    </visual>
  </link>

  <link name='right_wheel'>
    <inertial>
      <mass value="5.0"/>
      <origin xyz="0.0 0 0" rpy=" 0 1.5707 1.5707"/>
      <inertia
          ixx="0.1" ixy="0" ixz="0"
          iyy="0.1" iyz="0"
          izz="0.1"
      />
    </inertial>

    <collision name='right_wheel_collision'>
      <origin xyz="0 0 0" rpy=" 0 1.5707 1.5707"/> 
      <geometry>
        <cylinder length="0.05" radius="0.1"/>
      </geometry>
    </collision>

    <visual name='right_wheel_visual'>
      <origin xyz="0 0 0" rpy=" 0 1.5707 1.5707"/>
      <geometry>
        <cylinder length="0.05" radius="0.1"/>
      </geometry>
    </visual>
  </link>

  <link name='camera'>
      <xacro:inertial_cuboid_with_pose mass=".1" x_length="0.05" y_length="0.05" z_length="0.05" >
        <origin xyz="0.0 0 0" rpy=" 0 0 0"/>
      </xacro:inertial_cuboid_with_pose>  
  
    <collision name='camera_collision'>
      <origin xyz="0 0 0" rpy=" 0 0 0"/> 
      <geometry>
        <box size="0.05 0.05 0.05"/>
      </geometry>
    </collision>

    <visual name='camera_visual'>
      <origin xyz="0 0 0" rpy=" 0 0 0"/>
      <geometry>
        <box size="0.05 0.05 0.05"/>
      </geometry>
    </visual>
  </link>

  <link name='hokuyo'>
    <inertial>
      <mass value=".1"/>
      <origin xyz="0.0 0 0" rpy=" 0 0 0"/>
      <inertia
          ixx="1e-6" ixy="0" ixz="0"
          iyy="1e-6" iyz="0"
          izz="1e-6"
      />
    </inertial>

    <collision name='hokuyo_collision'>
      <origin xyz="0 0 0" rpy=" 0 0 0"/> 
      <geometry>
        <box size=".1 .1 .1"/>
      </geometry>
    </collision>

    <visual name='hokuyo_visual'>
      <origin xyz="0 0 0" rpy=" 0 0 0"/>
      <geometry>
        <mesh filename="package://udacity_bot/meshes/hokuyo.dae"/>
      </geometry>
    </visual>
  </link>
  
  <link name='chassis'>
    <pose>0 0 0.1 0 0 0</pose>
    <xacro:inertial_cylinder_with_pose mass="30.0" radius="0.2" z_length="0.6" >
      <origin xyz="0.0 0 0" rpy=" 0 0 0"/>
    </xacro:inertial_cylinder_with_pose>

    <collision name='collision'>
      <origin xyz="0 0 0" rpy=" 0 0 0"/> 
      <geometry>
        <cylinder length="0.6" radius="0.2"/>
      </geometry>
    </collision>

    <visual name='chassis_visual'>
      <origin xyz="0 0 0" rpy=" 0 0 0"/>
      <geometry>
        <cylinder length="0.6" radius="0.2"/>
      </geometry>
    </visual>
  </link>

  <link name='front_caster'>
    <collision name='front_caster_collision'>
      <origin xyz="0 0 0" rpy=" 0 0 0"/>
      <geometry>
        <sphere radius="0.05"/>
      </geometry>
      <surface>
        <friction>
          <ode>
            <mu>0</mu>
            <mu2>0</mu2>
            <slip1>1.0</slip1>
            <slip2>1.0</slip2>
          </ode>
        </friction>
      </surface>
    </collision>

    <visual name='front_caster_visual'>
      <origin xyz="0 0 0" rpy=" 0 0 0"/>
      <geometry>
        <sphere radius="0.05"/>
      </geometry>
    </visual>    
    
  </link>

  <link name='back_caster'>
      <collision name='back_caster_collision'>
      <origin xyz="0 0 0" rpy=" 0 0 0"/>
      <geometry>
        <sphere radius="0.05"/>
      </geometry>
      <surface>
        <friction>
          <ode>
            <mu>0</mu>
            <mu2>0</mu2>
            <slip1>1.0</slip1>
            <slip2>1.0</slip2>
          </ode>
        </friction>
      </surface>
    </collision>

    <visual name='back_caster_visual'>
      <origin xyz="0 0 0" rpy=" 0 0 0"/>
      <geometry>
        <sphere radius="0.05"/>
      </geometry>
    </visual>
  </link>

</robot>